
Reading dataset...
Traceback (most recent call last):
  File "gex_atac_sweep.py", line 47, in <module>
    gex_dim=gex_dim, atac_dim=atac_dim
  File "../../helpers/preprocessing.py", line 13, in __init__
    multiome = sc.read_h5ad(absolute_path)
  File "/h/angelo/miniconda3/envs/single_cell_env/lib/python3.7/site-packages/anndata/_io/h5ad.py", line 408, in read_h5ad
    with h5py.File(filename, "r") as f:
  File "/h/angelo/miniconda3/envs/single_cell_env/lib/python3.7/site-packages/h5py/_hl/files.py", line 533, in __init__
    fid = make_fid(name, mode, userblock_size, fapl, fcpl, swmr=swmr)
  File "/h/angelo/miniconda3/envs/single_cell_env/lib/python3.7/site-packages/h5py/_hl/files.py", line 226, in make_fid
    fid = h5f.open(name, flags, fapl=fapl)
  File "h5py/_objects.pyx", line 54, in h5py._objects.with_phil.wrapper
  File "h5py/_objects.pyx", line 55, in h5py._objects.with_phil.wrapper
  File "h5py/h5f.pyx", line 106, in h5py.h5f.open
FileNotFoundError: [Errno 2] Unable to open file (unable to open file: name = 'data/multimodal/GSE194122_openproblems_neurips2021_multiome_BMMC_processed.h5ad', errno = 2, error message = 'No such file or directory', flags = 0, o_flags = 0)